Workbook

Sheet Valuation
B4: Comparable Companies
B5: mEUR | C5: Min | D5: Median | E5: Average | F5: Max
B6: FY26 EBITDA | C6: 2.62 | D6: 2.62 | E6: 2.62 | F6: 2.62
B7: EV/EBITDA | C7: =Companies!S19 -> 7.024 | D7: =Companies!S20 -> 9.3032 | E7: =Companies!S22 -> 10.822171 | F7: =Companies!S21 -> 18.7771
B8: Enterprise Value | C8: =C6*C7 -> 18.40288 | D8: =D6*D7 -> 24.374384 | E8: =E6*E7 -> 28.354089 | F8: =F6*F7 -> 49.196002
B11: Precedent Transactions
B12: mEUR | C12: Min | D12: Median | E12: Average | F12: Max
B13: FY26 EBITDA | C13: 2.62 | D13: 2.62 | E13: 2.62 | F13: 2.62
B14: EV/EBITDA | C14: ='Relevant Transactions'!I15 -> 8.1 | D14: ='Relevant Transactions'!I16 -> 9.05 | E14: ='Relevant Transactions'!I18 -> 10.833333 | F14: ='Relevant Transactions'!I17 -> 18.7
B15: Enterprise Value | C15: =C13*C14 -> 21.222 | D15: =D13*D14 -> 23.711 | E15: =E13*E14 -> 28.383333 | F15: =F13*F14 -> 48.994

Sheet Precedent Transactions>>>

Sheet Transactions
B2: Index | C2: Target | D2: Type | E2: Status | F2: Announced | G2: Announcment Month | H2: Summary | I2: Deal Size ($Mn) | J2: Valuation ($Mn) | K2: Revenue ($Mn) | L2: EV/Sales | M2: EV/EBITDA | N2: EV/EBIT | O2: Buyers | P2: Sellers | Q2: Target Country | R2: Target Employees
B3: 37 | C3: Aarstad & Bjørnhaug Bemanning AS | D3: Company Acquisition | E3: finished | F3: Apr 08, 2026 | G3: 46120 | H3: Calviks, a Swedish investment firm, has signed a non-binding Letter of Intent to acquire Aarstad & Bjørnhaug Bemanning, a Norwegian staffing firm. The deal is part of Calviks' expansion strategy in the Norwegian market. The preliminary purchase price is approximately NOK 43.7 million, with potential earn-outs from 2026 to 2028. | I3: 4.1515 | J3: 4.515 | L3: 0.5 | M3: 4.3 | N3: 4.3 | O3: Calviks AB | Q3: NO | R3: 13
B4: 53 | C4: Greycoat Lumleys | D4: Carve-Out Acquisition | E4: finished | F4: Mar 31, 2026 | G4: 46112 | H4: Empresaria Group plc acquired the remaining 10% minority interest in its UK subsidiary, Greycoat Placements Limited (GP), from Deborah Salter, GP's managing director. This acquisition makes GP a wholly-owned subsidiary of Empresaria. | I4: 0.0635 | L4: 0.1 | M4: 1.1 | N4: 1 | O4: Empresaria Group plc | Q4: GB | R4: 238
B5: 18 | C5: Metric | D5: Company Acquisition | E5: finished | F5: Mar 24, 2026 | G5: 46105 | H5: Southfield Capital has acquired Metric Search, a UK-based executive search firm, in a $100 million deal. This acquisition marks an exit for UK-based investor BGF, who had backed Metric Search for 20 months. | I5: 100 | L5: 2.7 | M5: 12 | N5: 7.4 | O5: Southfield Capital | P5: Bgf | Q5: GB | R5: 216
B6: 23 | C6: Bemex Rekruttering AS | D6: Company Acquisition | E6: finished | F6: Mar 10, 2026 | G6: 46091 | H6: Calviks, an investment company, is acquiring Bemex Rekruttering, a Norwegian recruitment and temporary staffing company. The acquisition price is 19.3 million Norwegian Kroner on a debt-free basis, adjusted for net cash and working capital, which is approximately 18.5 million Swedish Kroner. This acquisition aligns with Calviks' strategy to build a Nordic platform in skilled labor provision through acquisitions and organic growth. Bemex Rekruttering is based in Bergen and generated 38 million Norwegian Kroner in revenue and approximately 4 million Norwegian Kroner in EBITDA last year. The transaction is expected to be completed by March 13. | I6: 1.8335 | L6: 0.5 | M6: 4.7 | N6: 4.7 | O6: Calviks AB | Q6: NO | R6: 13
B7: 14 | C7: Wise Group AB | D7: Company Acquisition | E7: finished | F7: Mar 04, 2026 | G7: 46085 | H7: Dahlgren Capital Active Equity AB has agreed to acquire one million shares in Wise Group AB from Stefan Rossi for 20 SEK per share, totaling 20 million SEK. This transaction will make Dahlgren Capital the new main owner of Wise Group, increasing their stake to 27.9% after this acquisition and a previously announced directed new share issue. | I7: 1.98 | L7: 0.3 | M7: 21.5 | N7: 5 | O7: Dahlgren Capital | Q7: SE | R7: 270
B8: 25 | C8: Linsco Ltd | D8: Company Acquisition | E8: finished | F8: Nov 12, 2025 | G8: 45973 | H8: AMC Private Equity has acquired Linsco, a Nottingham-based construction and civil engineering recruiter. The deal was supported by £6.75 million in funding from Bibby Financial Services and is expected to strengthen AMC's position in the construction recruitment market and accelerate its national expansion plans. Linsco will continue to operate under its existing brand. | I8: 8.5725 | L8: 0.2 | M8: 5.6 | N8: 5.3 | O8: AMC Private Equity | Q8: GB | R8: 271
B9: 13 | C9: NetJobs | D9: Company Acquisition | E9: finished | F9: Nov 11, 2025 | G9: 45972 | H9: Lane Capital AB agreed to acquire NetJobs Group AB in a reverse merger transaction for approximately SEK 130 million. The consideration includes 155,161,000 shares in NetJobs and a promissory note of SEK 5 million, totaling approximately SEK 131.9 million. After the acquisition, Lane Capital shareholders will hold approximately 82.7% of NetJobs shares. | I9: 12.87 | J9: 13.0581 | L9: 12.9 | M9: 9.4 | N9: 9.1 | Q9: SE
B10: 11 | C10: Barchester Healthcare | D10: Company Acquisition | E10: finished | F10: Oct 28, 2025 | G10: 45958 | H10: Welltower Inc. acquired Barchester Healthcare, the UK's second-largest nursing home operator, for 5.2 billion. This acquisition includes Barchester's portfolio of over 230 care homes and hospitals, a development pipeline of 21 new projects, and its property holding subsidiary, Limecay. Barchester's management team will remain in place, and operations will continue under the existing name. This deal makes Welltower the largest overseas investor in the UK's social care market. | I10: 6604 | L10: 5.1 | M10: 49.7 | N10: 47.5 | O10: Welltower™ Inc. (NYSE:WELL) | Q10: GB | R10: 5817
B11: 55 | C11: M+C Saatchi Group | D11: Company Acquisition | E11: finished | F11: Oct 21, 2025 | G11: 45951 | H11: Harwood Capital Management Group began building an equity stake in M&C Saatchi PLC in December 2020. This was a strategic, open-market stake-building exercise by an activist investor, not a single funding round. Harwood later surpassed the 5% disclosure threshold in late 2024, with its stake reaching approximately 6% by early 2026. The investment is classified as "Opportunistic" and "Engaged Value Investing," targeting M&C Saatchi because it was considered "sufficiently undervalued" after board changes. Harwood has since transitioned into an activist role, advocating for a break-up or piecemeal sale of the agency to unlock value. | J11: 190.5 | L11: 0.4 | M11: 4.8 | N11: 3.9 | O11: Harwood Capital Management Ltd | Q11: GB | R11: 1192
B12: 8 | C12: Gojob | D12: Company Acquisition | E12: finished | F12: Oct 01, 2025 | G12: 45931 | H12: Persol Holdings, a company based in Japan, has acquired a majority stake of 85% in GoJob, a French company, for €122 million. This deal values GoJob at €144 million. | I12: 134.2 | J12: 158.4 | L12: 0.9 | M12: 225.3 | N12: 33.2 | Q12: FR | R12: 532
B13: 30 | C13: Russell Taylor Group | D13: Carve-Out Acquisition | E13: finished | F13: Sep 30, 2025 | G13: 45930 | H13: The businesses and assets of Russell Taylor Group Limited (RTG) and Building Services Recruit Limited (BSR), both insolvent entities, were acquired by RTG Bidco Limited as part of a wider management buyout (MBO) of the Russell Taylor Group's businesses and assets following their entry into administration. The deal preserved 71 jobs. | I13: 6.35 | L13: 0.1 | M13: 5.2 | N13: 4.1 | R13: 97
B14: 7 | C14: Davidson | D14: Carve-Out Acquisition | E14: finished | F14: Sep 29, 2025 | G14: 45929 | H14: Genuit has acquired Davidson, a business known for its leading brands in plumbing and heating sectors, for £49 million. Davidson's brands, including Salamander Pumps, Cistermiser, Talon, and Keraflo, hold strong market positions primarily in the UK's repair, maintenance, and improvement sectors for residential and commercial segments. This acquisition is expected to enhance Genuit's Sustainable Building Solutions (SBS) business unit and leverage Davidson's focus on water-saving solutions. | I14: 62.23 | M14: 8.5 | O14: Genuit Group | Q14: GB | R14: 412
B15: 22 | C15: gap personnel | D15: Company Acquisition | E15: finished | F15: Apr 14, 2025 | G15: 45761 | H15: Rcapital has acquired Gap Personnel in a £23.5 million carve-out deal. The acquisition was supported by a funding facility from Secure Trust Bank Commercial Finance (STB CF). Gap Personnel plans to invest in IT infrastructure and operational efficiency under the new ownership. | I15: 29.845 | L15: 0.1 | M15: 8.1 | N15: 5.9 | O15: Rcapital | P15: BeNext, Open Up Group Inc. | Q15: GB | R15: 681
B16: 21 | C16: Montico | D16: Company Acquisition | E16: finished | F16: Mar 20, 2025 | G16: 45736 | H16: Job Solution Sweden Holding AB (publ) has acquired Montico AB, including some of its subsidiaries. The transaction was financed through a senior secured bond loan of 165 MSEK, which also repaid an existing loan of 30 MSEK from Nordea. Montico Invest AB, the former majority owner, reinvested part of the purchase price by subscribing to new shares in Job Solution for approximately 10 MSEK. The board has withdrawn its dividend proposal due to the bond conditions. | I16: 6.891004 | J16: 4.95 | L16: 0.1 | M16: 3.8 | N16: 3.2 | O16: Job Solution | Q16: SE | R16: 413
B17: 38 | C17: Sevenstep | D17: Company Acquisition | E17: finished | F17: Feb 27, 2025 | G17: 45715 | H17: Kelly, a leading specialty talent solutions provider, acquired the Sevenstep brand as part of its acquisition of Motion Recruitment Partners in 2024. This acquisition led to the formation of an integrated permanent hiring solutions business line, combining KellyOCG's global RPO specialty with Sevenstep's talent acquisition solutions. Amy Bush, formerly president of Sevenstep, was appointed to lead this new integrated business. | M17: 11.5 | O17: Kelly | Q17: US | R17: 348
B18: 40 | C18: Habberstad AS | D18: Company Acquisition | E18: finished | F18: Feb 18, 2025 | G18: 45706 | H18: B3 Consulting Group AB acquired a 51% stake in Habberstad As for NOK 15.8 million. Habberstad will continue to operate as a subsidiary with its existing management and branding. | I18: 1.501 | L18: 0.4 | M18: 5.2 | N18: 5.5 | O18: B3 Consulting Group | Q18: NO | R18: 65
B19: 43 | C19: April Six | D19: Company Acquisition | E19: finished | F19: Jan 02, 2025 | G19: 45659 | H19: Marketbridge, a US-based marketing and business consulting firm, has acquired April Six Technology & Science from The MISSION Group. This acquisition aims to integrate solutions for marketing and sales leaders, providing seamless, end-to-end marketing growth solutions for B2B and B2C clients globally. | I19: 21.541025 | L19: 0.5 | M19: 18.6 | N19: 17.7 | O19: Marketbridge | P19: The MISSION Group
B20: 17 | C20: Humanskills | D20: Company Acquisition | E20: finished | F20: Nov 06, 2024 | G20: 45602 | H20: B & Capital has acquired a majority stake in Humanskills, a specialist in digital professions. This marks the second buy-out for Humanskills, which had been accompanied by two minority funds for the past five years. The deal size is estimated to be between 15 million and 35 million euros. | I20: 16.5 | L20: 1.6 | M20: 27.1 | N20: 25.6 | O20: B & Capital | P20: Capital Croissance, Turenne Groupe | R20: 385
B21: 34 | C21: Croud | D21: Company Acquisition | E21: finished | F21: Nov 04, 2024 | G21: 45600 | H21: ECI Partners has acquired a majority stake in Croud, a global digital marketing agency. This acquisition was funded by a w7.6 million club loan from OakNorth, HSBC, Investec, and Barclays. The aim is to accelerate Croud's growth through further acquisitions and organic expansion. | I21: 98.552 | L21: 2.5 | M21: 18.6 | N21: 9.5 | O21: ECI Partners | P21: Ldc | Q21: GB | R21: 727
B22: 56 | C22: W Communications | D22: Company Acquisition | E22: finished | F22: Jul 11, 2024 | G22: 45484 | H22: Warren Johnson, founder and CEO of W Communications, sold a majority stake in his 14-year-old consumer agency to an Employee Ownership Trust (EOT). This move is intended to benefit current and future employees and set a foundation for future growth, including potential expansion and acquisitions. | J22: 50.8 | L22: 1.2 | M22: 10.3 | N22: 9.7 | Q22: GB | R22: 80
B23: 52 | C23: I Mille | D23: Company Acquisition | E23: finished | F23: Jun 26, 2024 | G23: 45469 | H23: TXT e-solutions S.p.A. has acquired 100% of the capital of I MILLE Srl, its three foreign subsidiaries (Imille Spain SL, Imille Start Spa (Chile), and Imille Brasil Agencia LTDA), and the agency Uasabi Srl. This acquisition aims to strengthen and diversify TXT's Digital Advisory division, particularly in the MarTech segment, by integrating I MILLE Group's creative consultancy and Uasabi's communication expertise for new generations. | L23: 0.7 | M23: 5.3 | O23: Txt Group | Q23: IT | R23: 164
B24: 5 | C24: Textkernel by Bullhorn | D24: Company Acquisition | E24: finished | F24: Jun 19, 2024 | G24: 45462 | H24: Main Capital Partners has sold Textkernel, an AI pioneer in recruitment, to Bullhorn for 300 million euros. | I24: 330 | L24: 13.8 | M24: 71.9 | N24: 54.2 | O24: Bullhorn | P24: Main Capital Partners | Q24: NL | R24: 84
B25: 6 | C25: Zellis | D25: Company Acquisition | E25: finished | F25: Apr 16, 2024 | G25: 45398 | H25: Funds advised by private equity firm Apax Partners LLP have reached a definitive agreement to acquire Zellis Group from Bain Capital in a deal worth 1.25bn. Zellis Group is a provider of payroll and HR software services. | I25: 1587.5 | L25: 10.4 | M25: 18.5 | N25: 12.3 | O25: Apax | P25: Bain Capital Ventures (BCV) | Q25: GB | R25: 1524
B26: 50 | C26: Lunghezza D'Onda S.r.l. | D26: Company Acquisition | E26: finished | F26: Apr 02, 2024 | G26: 45384 | H26: Websolute Spa acquired a 70% stake in Lunghezza d'Onda Srl for EUR3.5 million. The deal includes an option for Websolute to purchase the remaining 30% of shares within five years. The acquisition aims to ensure management continuity with the founding partners remaining as managing directors. | I26: 3.85 | L26: 3.8 | M26: 6 | O26: Websolute | AI-First Digital Agency | Q26: IT | R26: 7
B27: 41 | C27: Executive.se | D27: Company Acquisition | E27: finished | F27: Mar 26, 2024 | G27: 45377 | H27: Job Solution Sweden Holding AB agreed to acquire Serveoffice and Executive Partners Scandinavia from Hub Of Executives Ab for approximately SEK 6.8 million. The payment includes SEK 1 million in cash, SEK 4.1 million through reverses, and SEK 1.75 million through a new issue of shares. Performance-based additional purchase prices will be paid over three years. | I27: 0.6732 | L27: 0.1 | M27: 0.9 | N27: 0.7 | O27: Job Solution | R27: 7
B28: 9 | C28: hokify | D28: Company Acquisition | E28: finished | F28: Jan 17, 2024 | G28: 45308 | H28: karriere.at has acquired hokify, a German and Austrian job platform, for over 40 million euros. The founders of hokify sold all their shares to karriere.at, but hokify will remain entrepreneurially independent with its existing management team. | I28: 44 | J28: 44 | L28: 0.5 | M28: 0.8 | N28: 0.7 | O28: karriere.at | Q28: DE | R28: 60
B29: 54 | C29: Media Pop | D29: Company Acquisition | E29: finished | F29: Jan 01, 2024 | G29: 45292 | H29: LKN Wealth Capital Investors sold its stake in Media Pop, a Singaporean provider of social media applications and campaign management, to Grupa Wirtualna Polska, a group of companies operating in the media and e-commerce sectors. Deloitte Legal advised LKN Wealth Capital Investors, while Brzozowska & Barwinska advised Grupa Wirtualna Polska. | L29: 4.1 | M29: 9 | O29: Grupa Wirtualna Polska | P29: iWealth | Q29: SG | R29: 3
B30: 15 | C30: Fruition Group | D30: Company Acquisition | E30: finished | F30: Oct 19, 2023 | G30: 45218 | H30: Erisbeg, a private equity investor, has acquired a majority stake in Fruition IT and Fruition Consulting, both based in Leeds. The two companies will operate under a single holding company with Eolas Recruitment, another Erisbeg acquisition. Sarah Pawson, the founder of Fruition IT and Fruition Consulting, will retain a significant minority stake in the new holding company. | I30: 16.5 | L30: 0.6 | M30: 8.1 | N30: 8.1 | O30: erisbeg | Q30: GB | R30: 86
B31: 4 | C31: SD Worx | D31: Company Acquisition | E31: finished | F31: Aug 11, 2023 | G31: 45149 | H31: CVC, a British investment fund, is investing EUR 400 million into SD Worx, a Flanders-based HR services provider. This investment values SD Worx at EUR 1.77 billion (excluding debt) and will be used by SD Worx to develop more digital applications and complete new acquisitions. | I31: 440 | J31: 1947 | L31: 5.6 | M31: 19.7 | N31: 18.8 | O31: Cvc | R31: 4050
B32: 3 | C32: Broadbean | D32: Company Acquisition | E32: finished | F32: Jun 14, 2023 | G32: 45091 | H32: Veritone is acquiring Broadbean from CareerBuilder for $52 million. This acquisition is expected to create a "very defensible, end-to-end solution" in recruitment technology by combining Broadbean's candidate data and job board network with Veritone's programmatic company, Pandologic. | I32: 52 | L32: 2.1 | M32: 8.7 | N32: 6.1 | O32: Veritone | P32: CareerBuilder, Apollo Global Management, Inc. | Q32: US | R32: 167
B33: 32 | C33: Jellyfish | D33: Company Acquisition | E33: finished | F33: Jun 01, 2023 | G33: 45078 | H33: Brandtech Group acquired Jellyfish from Fimalac. This acquisition is part of Brandtech's strategy to expand its digital communication technology empire, bringing its total revenue to over $1 billion and its workforce to over 7,000 employees across 40 countries. Fimalac also became a shareholder in Brandtech as part of the deal. | I33: 500 | L33: 1.4 | M33: 24.7 | N33: 10.1 | O33: The Brandtech Group | P33: Fimalac | R33: 2272
B34: 49 | C34: Oplana Manufacturing Services | D34: Company Acquisition | E34: finished | F34: Apr 28, 2023 | G34: 45044 | H34: Job Solution Sweden Holding AB (publ) has agreed to acquire 100% of the shares in Oplana AB from Limstickan AB. The preliminary purchase price is 14.5 MSEK on a cash and debt-free basis, which includes a company valuation of 12.8 MSEK plus adjusted working capital and net cash. The payment will be a combination of cash and shares in Job Solution. The transaction is subject to regulatory approval. | I34: 1.4355 | J34: 1.2672 | L34: 0.4 | M34: 2.6 | N34: 2.6 | O34: Job Solution | Q34: SE | R34: 2
B35: 44 | C35: Netum Buutti | D35: Company Acquisition | E35: finished | F35: Aug 10, 2023 | G35: 45026 | H35: Netum Group Plc is acquiring the entire share capital of Buutti Oy, an IT service company specializing in IT consulting and software development. This acquisition aligns with Netum's strategy to expand its service offerings, particularly in embedded systems and training, and to grow its corporate customer segment. The deal is expected to close on September 1, 2023. | I35: 11 | J35: 11 | L35: 1.1 | M35: 9.1 | N35: 9.1 | O35: Netum | Q35: FI | R35: 43
B36: 29 | C36: Lunos | D36: Company Acquisition | E36: finished | F36: May 28, 2023 | G36: 45013 | H36: Volution Group plc has acquired Lunos, a Slovenian specialist in ventilation technology, in a deal valued up to €40 million. | I36: 44 | L36: 4 | M36: 11.1 | O36: Volution Group plc | R36: 7
B37: 57 | C37: upsource by solutions | D37: Company Acquisition | E37: finished | F37: Mar 20, 2023 | G37: 45005 | H37: STC Capital, through its subsidiary solutions by stc, acquired 100% of Contact Centers Company (CCC) for SAR 450 million. This acquisition is part of stc's "DARE 2.0" strategy to expand into the Business Process Outsourcing (BPO) market. The deal was completed on April 3, 2023, and CCC was later rebranded as "Upsource by Solutions" in February 2025. | M37: 4.4 | O37: solutions by stc | P37: stc, ESM Business Performance | R37: 4548
B38: 19 | C38: Blue Arrow | D38: Carve-Out Acquisition | E38: finished | F38: Mar 03, 2023 | G38: 44988 | H38: Twenty20 Capital acquired seven specialized staffing and workforce solution brands from Impellam PLC, including Blue Arrow, Career Teachers, Global Medics, Medacs Healthcare, Litmus, and Tate, in a strategic acquisition/carve-out. This deal was completed on March 3, 2023, and was supported by a £70 million asset-based lending facility from Close Brothers Invoice Finance. The acquisition added over £600 million in revenue to Twenty20 Capital's portfolio. | I38: 88.9 | L38: 0.3 | M38: 8.4 | N38: 7.5 | O38: RSS Global, Twenty20 Capital | P38: Impellam Group | Q38: GB | R38: 3503
B39: 46 | C39: Connex Marketing Group | D39: Company Acquisition | E39: finished | F39: Feb 01, 2023 | G39: 44958 | H39: Awardit AB has acquired 100% of Connex Marketing GmbH, a leading Austrian loyalty and gift card company. The total purchase price is approximately 10.7 MEUR, paid partly in cash (7.2 MEUR) and partly in Awardit shares (3.5 MEUR). This acquisition aims to consolidate Awardit's position in the DACH region and expand into CEE countries and the UK. | I39: 11.77 | J39: 11.77 | M39: 7.1 | N39: 6.4 | O39: Awardit AB | Q39: AT | R39: 107
B40: 47 | C40: Craftware | D40: Company Acquisition | E40: finished | F40: Jan 16, 2023 | G40: 44942 | H40: Craftware, a software development firm utilizing CRM for commercial services, was acquired for $30,274,591. The acquisition was announced on December 7, 2020. | I40: 30.274591 | L40: 0.4 | M40: 2.9 | N40: 2.8 | O40: Visma
B41: 36 | C41: Quest Consulting | D41: Company Acquisition | E41: finished | F41: Aug 30, 2022 | G41: 44803 | H41: Job Solution Sweden Holding AB has acquired 100% of the shares in Quest Consulting Sverige AB from Qu3st Holding AB. The initial purchase price is 13.6 MSEK on a cash and debt-free basis. Quest Consulting specializes in consulting and interim services within IT, Technology, Administration, HR, and Economics. | I41: 1.3464 | L41: 0.7 | M41: 3.1 | N41: 3.1 | O41: Job Solution | P41: Qlife | Q41: SE
...

Sheet Relevant Transactions
B3: Main Comparable Transactions
B4: Company | C4: Country | D4: Date | E4: Segment | F4: Deal Size (US$M) | G4: Valuation (US$M) | H4: EV/Sales | I4: EV/EBITDA | J4: EV/EBIT | K4: Buyer | L4: Relevance to Michelscom
B6: Metric Search | C6: 🇬🇧 GB | D6: 46082 | E6: Exec Search | F6: 100 | G6: N/D | H6: 2.7 | I6: 12 | J6: 7.4 | K6: Southfield Capital | L6: ⭐⭐ UK executive search agency, 216 employees — similar agency model, good multiples reference
B7: NetJobs Group AB | C7: 🇸🇪 SE | D7: 45962 | E7: Job Board / Recruiting | F7: 12.9 | G7: 13.1 | H7: 12.9 | I7: 9.4 | J7: 9.1 | K7: Lane Capital AB | L7: ⭐⭐ Nordic online recruiting platform — smaller scale, good EV/EBITDA comp
B8: gap personnel | C8: 🇬🇧 GB | D8: 45748 | E8: Staffing Agency | F8: 29.8 | G8: N/D | H8: 0.1 | I8: 8.1 | J8: 5.9 | K8: Rcapital (PE) | L8: ⭐ Staffing agency carve-out — low EV/Sales due to low-margin staffing; PE comp
B9: Fruition Group | C9: 🇬🇧 GB | D9: 45200 | E9: IT Recruitment Agency | F9: 16.5 | G9: N/D | H9: 0.6 | I9: 8.1 | J9: 8.1 | K9: Erisbeg (PE) | L9: ⭐⭐ SME recruitment agency, 86 employees — PE acquisition, similar size range
B10: SD Worx | C10: 🇧🇪 BE | D10: 45139 | E10: HR Software / Services | F10: 440 | G10: 1947 | H10: 5.6 | I10: 18.7 | J10: 18.8 | K10: CVC (PE) | L10: ⭐ Large HR platform — useful upper-end benchmark for tech-enabled HR services multiples
B11: Broadbean | C11: 🇺🇸 US | D11: 45078 | E11: Recruiting Tech | F11: 52 | G11: N/D | H11: 2.1 | I11: 8.7 | J11: 6.1 | K11: Veritone ← CareerBuilder | L11: ⭐⭐ Recruitment marketing / job distribution tech; smaller scale but same workflow
B15: Min | H15: =MIN(H5:H12) -> 0.1 | I15: =MIN(I5:I12) -> 8.1 | J15: =MIN(J5:J12) -> 5.9
B16: Median | H16: =MEDIAN(H5:H12) -> 2.4 | I16: =MEDIAN(I5:I12) -> 9.05 | J16: =MEDIAN(J5:J12) -> 7.75
B17: Max | H17: =MAX(H5:H12) -> 12.9 | I17: =MAX(I5:I12) -> 18.7 | J17: =MAX(J5:J12) -> 18.8
B18: Average | H18: =AVERAGE(H5:H12) -> 4 | I18: =AVERAGE(I5:I12) -> 10.833333 | J18: =AVERAGE(J5:J12) -> 9.2333333
B20: Source: Inven transaction database · Search view tsv_T2d9dz7hRD · ⭐⭐⭐ = closest peers · ⭐⭐ = directly comparable · ⭐ = broader sector benchmark · N/D = not disclosed
B21: Additional Transactions
B23: Humanskills | C23: 🇫🇷 FR | D23: 45597 | E23: Digital Talent Agency | F23: 16.5 | G23: N/D | H23: 1.6 | I23: 27.1 | J23: 25.6 | K23: B & Capital (PE) | L23: ⭐⭐ Digital professions talent agency — PE buyout, €15–35M deal, 385 employees
B24: Textkernel (Bullhorn) | C24: 🇳🇱 NL | D24: 45444 | E24: AI Recruiting Software | F24: 330 | G24: N/D | H24: 13.8 | I24: 71.9 | J24: 54.2 | K24: Bullhorn ← Main Capital | L24: ⭐ AI-powered recruiting software — premium multiples; useful for tech-forward positioning
B25: hokify | C25: 🇩🇪 DE/AT | D25: 45292 | E25: Job Platform | F25: 44 | G25: 44 | H25: 0.5 | I25: 0.8 | J25: 0.7 | K25: karriere.at | L25: ⭐⭐ German-Austrian digital job platform, 60 employees — size comparable, same market
B26: Bemex Rekruttering | C26: 🇳🇴 NO | D26: 46082 | E26: Staffing / Recruitment | F26: 1.8 | G26: N/D | H26: 0.5 | I26: 4.7 | J26: 4.7 | K26: Calviks AB | L26: ⭐⭐ Small Nordic recruitment firm, 13 employees — very small deal, useful lower-end comp
B27: HiOffice Group GmbH | C27: 🇩🇪 DE | D27: 45901 | E27: Social Recruiting | F27: N/D | G27: N/D | H27: N/D | I27: N/D | J27: N/D | K27: Odewald KMU | L27: ⭐⭐⭐ Closest peer — German DACH social recruiting agency for blue-collar, 54 employees (PE buyout)
B28: milch & zucker GmbH | C28: 🇩🇪 DE | D28: 45261 | E28: HR Tech / Agency | F28: N/D | G28: N/D | H28: N/D | I28: N/D | J28: N/D | K28: Bertelsmann / EMBRACE | L28: ⭐⭐⭐ German HR-Tech & HR-Agency combo (recruiting + retention + tech) — near-identical profile
B29: QAPA (Adecco) | C29: 🇫🇷 FR | D29: 44440 | E29: Digital Workforce Platform | F29: 71.5 | G29: N/D | H29: 14.7 | I29: N/D | J29: N/D | K29: Adecco | L29: ⭐⭐ Fully-digital recruitment platform acquired by strategic — high EV/Sales for tech-enabled model

Sheet Comparable Companies>>>

Sheet Companies
B2: Main Comparable Companies
B3: Company ID | C3: Company name | D3: Description | E3: Country | F3: Website | G3: Employees Count (LinkedIn) | H3: Ownership Type | I3: Latest revenue (MUSD) | J3: Latest revenue 3yr CAGR (2022 - 2025) | K3: TEV | L3: Reported revenue (M) | M3: Latest EBITDA (MUSD) | P3: Latest EBITDA % | Q3: Reported EBITDA (M) | R3: Latest EV/Sales | S3: Latest EV/EBITDA | T3: EV/EBIT Historical EV 2025 | U3: Latest employee 3yr CAGR (2022 - 2025) | V3: Reported EBITDA currency | W3: Latest EV/Sales year | X3: Latest EV/EBITDA year | Y3: Financials source | Z3: FX rate | AA3: FX date
B4: 11028540 | C4: Grupa Pracuj | D4: Grupa Pracuj is an HR Tech company that connects job seekers with employers and provides recruitment and employee development services. They offer innovative solutions, including AI-driven job matching, to help businesses streamline their hiring processes. Their clients range from small enterprises to large corporations across various industries, seeking effective talent acquisition and management strategies. | E4: Poland | F4: http://pracujwgp.pl | G4: 590 | H4: Public | I4: 216.1122 | J4: 0.10056705 | K4: =M4*S4 -> 859.42735 | L4: 216.1122 | M4: 97.524778 | P4: 0.45126918 | Q4: 97.524778 | R4: 3.9768 | S4: 8.8124 | T4: 9.9036 | U4: 0.021822889 | V4: USD | W4: 2025 | X4: 2025 | Y4: Public reported FY2025 (Stock exchange)
B5: 5280480 | C5: Amadeus Fire | D5: Amadeus Fire is a staffing agency specializing in recruitment and placement services in the commercial and IT sectors. They connect businesses with qualified candidates, offering services such as interim management and IT freelancing. Their clientele includes various companies seeking efficient hiring solutions. With over 20 locations across Germany, they leverage their regional presence to understand local job markets better. | E5: Germany | F5: http://amadeus-fire.de | G5: 1135 | H5: Public | I5: 414.85669 | J5: -0.036945464 | K5: =M5*S5 -> 429.38361 | L5: 414.85669 | M5: 49.033186 | P5: 0.11819307 | Q5: 49.033186 | R5: 1.035 | S5: 8.757 | T5: 30.8672 | U5: 0.033556563 | V5: USD | W5: 2025 | X5: 2025 | Y5: Public reported FY2025 (Stock exchange)
B6: 18285512 | C6: Eezy Oyj | D6: Eezy is a staffing agency that provides a range of employment services, including personnel leasing, recruitment, and training. The company serves both businesses and individuals, facilitating job placements and workforce management. With a focus on various industries, Eezy aims to connect job seekers with suitable employment opportunities while assisting companies in finding qualified personnel. | E6: Finland | F6: http://eezy.fi | G6: 666 | H6: Public | I6: 158.97705 | J6: -0.17439522 | K6: =M6*S6 -> 74.01089 | L6: 158.97705 | M6: 10.536858 | P6: 0.066279111 | Q6: 10.536858 | R6: 0.4655 | S6: 7.024 | T6: 175.791 | U6: 0.15610954 | V6: USD | W6: 2025 | X6: 2025 | Y6: Public reported FY2025 (Stock exchange)
B7: 501430 | C7: FDM Group | D7: FDM Group is a consulting firm specializing in tech and business talent solutions. They provide training and development programs to help individuals build careers in technology while assisting businesses in enhancing productivity and innovation through skilled talent. Their services include consulting and project delivery, focusing on bridging the digital skills gap for their clients. | E7: United Kingdom (UK) | F7: http://fdmgroup.com | G7: 4145 | H7: Public | I7: 234.92666 | J7: -0.18637283 | K7: =M7*S7 -> 173.62768 | L7: 234.92666 | M7: 24.179097 | P7: 0.1029219 | Q7: 24.179097 | R7: 0.7391 | S7: 7.1809 | T7: 9.9668 | U7: -0.14732004 | V7: USD | W7: 2025 | X7: 2025 | Y7: Public reported FY2025 (Stock exchange)
B8: 5174553 | C8: Ogunsen AB | D8: Ogunsen AB is a consulting and recruitment firm specializing in providing expert services in talent acquisition and management. They focus on helping organizations find qualified specialists and leaders, particularly in finance and related fields. With a commitment to sustainability and diversity, Ogunsen aims to enhance the effectiveness of their clients' workforce and contribute to a more inclusive labor market. | E8: Sweden | F8: http://ogunsen.se | G8: 10 | H8: Public | I8: 45.78848 | J8: -0.042821305 | K8: =M8*S8 -> 33.932719 | L8: 45.78848 | M8: 2.966432 | P8: 0.064785553 | Q8: 2.966432 | R8: 0.7411 | S8: 11.4389 | T8: 18.0383 | U8: 0.1856311 | V8: USD | W8: 2025 | X8: 2025 | Y8: Public reported FY2025 (Stock exchange)
B9: 40865279 | C9: PageGroup | D9: PageGroup is a recruitment agency specializing in providing talent solutions for organizations. They offer services such as executive search and recruitment outsourcing, helping businesses find qualified candidates across various industries. With a global presence, PageGroup focuses on changing lives by connecting people with job opportunities. | E9: United Kingdom (UK) | F9: http://page.com | G9: 2106 | H9: Public | I9: 2110.4193 | J9: -0.070838113 | K9: =M9*S9 -> 1105.1671 | L9: 2110.4193 | M9: 103.28858 | P9: 0.048942206 | Q9: 103.28858 | R9: 0.5237 | S9: 10.6998 | T9: 40.0711 | U9: -0.027534294 | V9: USD | W9: 2025 | X9: 2025 | Y9: Public reported FY2025 (Stock exchange)
B10: 8675714 | C10: Robert Walters | D10: Robert Walters is a recruitment agency that specializes in connecting businesses with top talent across various sectors including accounting, finance, legal, and technology. The company provides tailored recruitment solutions and talent advisory services to help organizations find the right candidates and assist individuals in their job search. With a strong presence in the UK, Robert Walters operates through multiple offices to serve its clients effectively. | E10: United Kingdom (UK) | F10: http://robertwalters.co.uk | G10: 4508 | H10: Public | I10: 1032.4892 | J10: -0.10774162 | K10: =M10*S10 -> 173.50366 | L10: 1032.4892 | M10: 10.57472 | P10: 0.010241966 | Q10: 10.57472 | R10: 0.168 | S10: 16.4074 | T10: -9.0524 | U10: -0.11977409 | V10: USD | W10: 2025 | X10: 2025 | Y10: Public reported FY2025 (Stock exchange)
B11: 8454443 | C11: Hays | D11: Hays is a recruitment agency specializing in qualified, professional, and skilled recruitment. The company connects jobseekers with employers across various industries, providing services such as recruitment process outsourcing and executive search. With a global presence and a diverse range of expertise, Hays supports both candidates and businesses in navigating the labor market effectively. | E11: United Kingdom (UK) | F11: http://haysplc.com | G11: 31439 | H11: Public | I11: 8733.3969 | J11: 0.00091484423 | K11: =M11*S11 -> 1689.7135 | L11: 8733.3969 | M11: 103.36789 | P11: 0.011835932 | Q11: 103.36789 | R11: 0.1935 | S11: 16.3466 | T11: 81.9428 | U11: 0.073027151 | V11: USD | W11: 2025 | X11: 2025 | Y11: Public reported FY2025 (Stock exchange)
B12: 12444477 | C12: Brunel | D12: Brunel is a recruitment agency specializing in workforce solutions across various industries including Conventional Energy, Mining, and Life Sciences. The company connects skilled professionals with businesses seeking talent, offering services such as contract hire, direct hire, and consulting solutions. Brunel operates globally, providing tailored support to enhance operational efficiency for its clients. | E12: Netherlands | F12: http://brunel.net | G12: 5307 | H12: Public | I12: 1389.309 | J12: 0.010005959 | K12: =M12*S12 -> 460.95447 | L12: 1389.309 | M12: 50.992231 | P12: 0.036703305 | Q12: 50.992231 | R12: 0.3318 | S12: 9.0397 | T12: 23.4707 | U12: 0.013814435 | V12: USD | W12: 2025 | X12: 2025 | Y12: Public reported FY2025 (Stock exchange)
B13: 5161314 | C13: NGS Group | D13: NGS Group AB is a recruitment agency specializing in executive search, staffing, and interim management services. They cater to businesses and organizations in various sectors, including healthcare and social services, by providing expert recruitment solutions to meet their staffing needs. NGS Group operates through a network of specialists and has a strong presence in the Nordic market. | E13: Sweden | F13: http://ngsgroup.se | G13: 368 | H13: Public | I13: 29.25088 | J13: -0.20869502 | K13: =M13*S13 -> 8.1513644 | L13: 29.25088 | M13: 0.434112 | P13: 0.014840989 | Q13: 0.434112 | R13: 0.2787 | S13: 18.7771 | T13: -182.5547 | U13: 0.76437545 | V13: USD | W13: 2025 | X13: 2025 | Y13: Public reported FY2025 (Stock exchange)
B14: 8895426 | C14: PION Group AB | D14: PION Group AB is a consulting and recruitment firm that specializes in maximizing organizational performance through strategic consulting and skilled recruitment services. They operate under various brands, providing expertise in IT, tech, and human resources to businesses and organizations across Sweden, Norway, and Finland. | E14: Sweden | F14: http://piongroup.se | G14: 20 | H14: Public | I14: 146.06835 | J14: -0.1217303 | K14: =M14*S14 -> 29.121721 | L14: 146.06835 | M14: 2.79072 | P14: 0.019105576 | Q14: 2.79072 | R14: 0.1994 | S14: 10.4352 | T14: -50.3126 | U14: 0.25992105 | V14: USD | W14: 2025 | X14: 2025 | Y14: Public reported FY2025 (Stock exchange)
B15: 3595177 | C15: Ework Group | D15: Ework Group is a talent solutions provider specializing in connecting businesses with skilled professionals across various industries. They offer services such as consulting, recruitment, and total talent management, helping organizations optimize their workforce and project execution. With a strong network of professionals, Ework Group supports clients in navigating the complexities of talent acquisition and management. | E15: Sweden | F15: http://eworkgroup.com | G15: 548 | H15: Public | I15: 1420.2198 | J15: -0.05086174 | K15: =M15*S15 -> 184.70652 | L15: 1420.2198 | M15: 19.307235 | P15: 0.013594539 | Q15: 19.307235 | R15: 0.1301 | S15: 9.5667 | T15: 14.5376 | U15: -0.032978838 | V15: USD | W15: 2025 | X15: 2025 | Y15: Public reported FY2025 (Stock exchange)
... B17: 2446778 | C17: Adecco | D17: Adecco is a recruitment agency that specializes in staffing solutions for businesses and job seekers. The company offers services such as temporary and permanent placement, training, and outsourcing to help organizations manage their workforce effectively. Adecco serves a diverse range of industries, providing tailored solutions to meet the unique needs of its clients. | E17: Switzerland | F17: http://adecco.com | G17: 205090 | H17: Public | I17: 26507.911 | J17: -0.0057751746 | K17: =M17*S17 -> 7939.9417 | L17: 26507.911 | M17: 931.37146 | P17: 0.035135603 | Q17: 931.37146 | R17: 0.2995 | S17: 8.525 | T17: 11.5809 | U17: 0.43279917 | V17: USD | W17: 2025 | X17: 2025 | Y17: Public reported FY2025 (Stock exchange)
B19: Min | R19: =MIN(R4:R17) -> 0.1301 | S19: =MIN(S4:S17) -> 7.024 | T19: =MIN(T4:T17) -> -182.5547
B20: Median | R20: =MEDIAN(R4:R17) -> 0.3215 | S20: =MEDIAN(S4:S17) -> 9.3032 | T20: =MEDIAN(T4:T17) -> 14.07015
B21: Max | R21: =MAX(R4:R17) -> 3.9768 | S21: =MAX(S4:S17) -> 18.7771 | T21: =MAX(T4:T17) -> 175.791
B22: Average | R22: =AVERAGE(R4:R17) -> 0.67095714 | S22: =AVERAGE(S4:S17) -> 10.822171 | T22: =AVERAGE(T4:T17) -> 13.418071
B24: Additional Comparable Companies
B25: 7215898 | C25: Synergie France | D25: Synergie is an employment agency specializing in temporary staffing, recruitment, and HR consulting services. They serve businesses across various sectors, providing tailored solutions for workforce management and recruitment challenges. With a network of agencies, Synergie connects qualified candidates with job opportunities while supporting companies in their hiring processes. | E25: France | F25: http://synergie.fr | G25: 4773 | H25: Public | I25: 3698.112 | J25: 0.035869536 | L25: 3698.112 | M25: 153.33952 | P25: 0.041464272 | Q25: 153.33952 | R25: 0.1291 | S25: 3.1141 | T25: 4.3016 | U25: -0.018628702 | V25: USD | W25: 2025 | X25: 2025 | Y25: Public reported FY2025 (Stock exchange)
B26: 1477589 | C26: Staffline Recruitment Limited | D26: Staffline Recruitment Limited is a recruitment agency that specializes in providing staffing solutions for various industries, including logistics, manufacturing, and food production. The company connects businesses with qualified candidates for temporary, permanent, and fixed-term positions, addressing the workforce needs of its clients. Staffline operates through a network of branches and onsite services across the UK and Ireland. | E26: United Kingdom (UK) | F26: http://staffline.co.uk | G26: 2396 | H26: Public | I26: 1462.8803 | J26: 0.055740146 | L26: 1462.8803 | M26: 21.017256 | P26: 0.014367037 | Q26: 21.017256 | R26: 0.0517 | S26: 3.6013 | T26: 4.4046 | U26: 0.1166112 | V26: USD | W26: 2025 | X26: 2025 | Y26: Public reported FY2025 (Stock exchange)
B27: 1335665 | C27: Empresaria Group plc | D27: Empresaria Group plc is a staffing agency that operates across six diversified sectors, including Professional, IT, Healthcare, and Offshore Services. The company provides tailored recruitment solutions to businesses, helping them find exceptional talent to meet their operational needs. With a presence in multiple countries, Empresaria is committed to positively impacting the lives of people through its staffing services. | E27: United Kingdom (UK) | F27: http://empresaria.com | G27: 130 | H27: Public | I27: 315.91976 | J27: -0.029297465 | L27: 315.91976 | M27: 15.994264 | P27: 0.050627615 | Q27: 15.994264 | R27: 0.1516 | S27: 2.9934 | T27: 7.874 | U27: 0.044751092 | V27: USD | W27: 2025 | X27: 2025 | Y27: Public reported FY2025 (Stock exchange)
B28: 3593079 | C28: Gattaca | D28: Gattaca PLC is a recruitment agency specializing in STEM sectors, providing talent solutions for engineering and technology companies. They help businesses tackle workforce challenges by connecting them with skilled professionals. Gattaca operates in various industries, including aerospace and energy, and focuses on delivering project management and consulting services to meet client needs. | E28: United Kingdom (UK) | F28: http://gattacaplc.com | G28: 244 | H28: Public | I28: 527.28198 | J28: -0.0041213881 | L28: 527.28198 | M28: 5.4301187 | P28: 0.01029832 | Q28: 5.4301187 | R28: 0.0302 | S28: 2.9305 | T28: 4.4636 | U28: -0.34692673 | V28: USD | W28: 2025 | X28: 2025 | Y28: Public reported FY2025 (Stock exchange)
B29: 2122004 | C29: Freelance.com | D29: Freelance.com is a talent management service that connects businesses with freelancers and small to medium enterprises. It offers solutions for sourcing talent, managing payroll, and providing administrative support, catering to the needs of organizations seeking flexible workforce solutions. The company operates a digital platform that facilitates project management and training services for its users. | E29: France | F29: http://freelance.com | G29: 2466 | H29: Public | I29: 1200.985 | J29: 0.095711533 | L29: 1200.985 | M29: 32.64087 | P29: 0.027178415 | Q29: 32.64087 | R29: 0.1388 | S29: 5.1085 | T29: 6.3618 | U29: 0.112084 | V29: USD | W29: 2025 | X29: 2025 | Y29: Public reported FY2025 (Stock exchange)
B30: 1177943 | C30: RTC Group Plc | D30: RTC Group Plc is a recruitment agency that specializes in providing staffing solutions for both white and blue-collar positions across various sectors, including engineering, construction, and transportation. The company operates through its brands, such as ATA Recruitment and Ganymede, to deliver tailored recruitment services to businesses and organizations in need of qualified personnel. | E30: United Kingdom (UK) | F30: http://rtcgroupplc.co.uk | G30: 21 | H30: Public | I30: 126.28595 | J30: 0.099347497 | L30: 126.28595 | M30: 4.3475318 | P30: 0.034426092 | Q30: 4.3475318 | R30: 0.1125 | S30: 3.267 | T30: 4.1328 | U30: 0.033923876 | V30: USD | W30: 2025 | X30: 2025 | Y30: Public reported FY2025 (Stock exchange)
B31: 3391652 | C31: SThree | D31: SThree is a consultancy specializing in STEM workforce solutions, connecting skilled professionals with organizations in need of expertise in science, technology, engineering, and mathematics. The company operates through various specialist brands, providing recruitment and strategic consulting services to businesses across multiple sectors, including life sciences and financial services. | E31: United Kingdom (UK) | F31: http://sthree.com | G31: 7883 | H31: Public | I31: 1721.3053 | J31: -0.073894132 | L31: 1721.3053 | M31: 59.852915 | P31: 0.034771818 | Q31: 59.852915 | R31: 0.1779 | S31: 5.1162 | T31: 8.3924 | U31: 0.053291056 | V31: USD | W31: 2025 | X31: 2025 | Y31: Public reported FY2025 (Stock exchange)
